Workbook
Name Aporte: 'Calculadora Inteligente'!$D$15
Name cenário10: 'Calculadora Inteligente'!$C$24
Name cenário2: 'Calculadora Inteligente'!$C$22
Name cenário20: 'Calculadora Inteligente'!$C$25
Name cenário30: 'Calculadora Inteligente'!$C$26
Name cenário5: 'Calculadora Inteligente'!$C$23
Name perfilderisco: 'Calculadora Inteligente'!$C$28
Name Periodo: 'Calculadora Inteligente'!$D$16
Name premissaanos: 'Calculadora Inteligente'!$A$18
Name premissadesugestão: 'Calculadora Inteligente'!$A$11
Name Renda_mensal: 'Calculadora Inteligente'!$D$19
Name Rendimento: 'Calculadora Inteligente'!$D$10
Name Salário: 'Calculadora Inteligente'!$D$9
Name sugestãoaporte: 'Calculadora Inteligente'!$D$11
Name Taxa: 'Calculadora Inteligente'!$D$17
Name VFdoPL: 'Calculadora Inteligente'!$D$18

Sheet Calculadora Inteligente
B3: Calculadora Inteligente
B8: PREMISSAS
B9: Salário | D9: 20000
B10: Rendimendo da carteira | D10: 0.01
A11: 0.3 | B11: Sugestão de investimento | D11: =Salário*A11 -> 6000
B14: CALCULADORA INTELIGENTE
B15: Investimento mensal | D15: 50000
B16: Periodo (Em anos) | D16: 10
B17: Taxa de rendimento mensal do período | D17: 0.012
A18: 12 | B18: Patrimônio no Período Final | D18: =FV(Taxa,Periodo*A18,Aporte*-1) -> 13269470
B19: Renda mensal através de dividendos | D19: =VFdoPL*Rendimento -> 132694.7
B21: CENÁRIOS | D21: DIVIDENDOS
A22: 2 | B22: Quanto de valor investido em 2 anos | C22: =FV(Taxa,A22*premissaanos,Aporte*-1) -> 1381136.7 | D22: =cenário2*Rendimento -> 13811.367
A23: 5 | B23: Quanto de valor investido em 5 anos | C23: =FV(Taxa,A23*premissaanos,Aporte*-1) -> 4356863.6 | D23: =cenário5*Rendimento -> 43568.636
A24: 10 | B24: Quanto de valor investido em 10 anos | C24: =FV(Taxa,A24*premissaanos,Aporte*-1) -> 13269470 | D24: =cenário10*Rendimento -> 132694.7
A25: 20 | B25: Quanto de valor investido em 20 anos | C25: =FV(Taxa,A25*premissaanos,Aporte*-1) -> 68797858 | D25: =cenário20*Rendimento -> 687978.58
A26: 30 | B26: Quanto de valor investido em 30 anos | C26: =FV(Taxa,A26*premissaanos,Aporte*-1) -> 3.0116599e+08 | D26: =cenário30*Rendimento -> 3011659.9
B28: PERFIL | C28: Agressivo
B29: Investimento Mensal | C29: =Aporte -> 50000
B31: Tipo de FII | D31: Valor a investir
B32: PAPEL | C32: =INDEX('FII''s'!$B$1:$E$7,MATCH('Calculadora Inteligente'!$B32,'FII''s'!$B$1:$B$7,0),MATCH(perfilderisco,'FII''s'!$B$1:$E$1,0)) -> 0.5 | D32: =C32*$C$29 -> 25000
B33: TIJOLO | C33: =INDEX('FII''s'!$B$1:$E$7,MATCH('Calculadora Inteligente'!$B33,'FII''s'!$B$1:$B$7,0),MATCH(perfilderisco,'FII''s'!$B$1:$E$1,0)) -> 0.1 | D33: =C33*$C$29 -> 5000
B34: HÍBRIDOS | C34: =INDEX('FII''s'!$B$1:$E$7,MATCH('Calculadora Inteligente'!$B34,'FII''s'!$B$1:$B$7,0),MATCH(perfilderisco,'FII''s'!$B$1:$E$1,0)) -> 0.05 | D34: =C34*$C$29 -> 2500
B35: FOFs | C35: =INDEX('FII''s'!$B$1:$E$7,MATCH('Calculadora Inteligente'!$B35,'FII''s'!$B$1:$B$7,0),MATCH(perfilderisco,'FII''s'!$B$1:$E$1,0)) -> 0.05 | D35: =C35*$C$29 -> 2500
B36: DESENVOLVIMENTO | C36: =INDEX('FII''s'!$B$1:$E$7,MATCH('Calculadora Inteligente'!$B36,'FII''s'!$B$1:$B$7,0),MATCH(perfilderisco,'FII''s'!$B$1:$E$1,0)) -> 0.2 | D36: =C36*$C$29 -> 10000
B37: HOTELARIAS | C37: =INDEX('FII''s'!$B$1:$E$7,MATCH('Calculadora Inteligente'!$B37,'FII''s'!$B$1:$B$7,0),MATCH(perfilderisco,'FII''s'!$B$1:$E$1,0)) -> 0.1 | D37: =C37*$C$29 -> 5000
B38: TOTAL | C38: =SUM(C32:C37) -> 1 | D38: =SUM(D32:D37) -> 50000
B41: TESTE DE SENSIBILIDADE
D42: Quantos anos investindo
B43: Taxa de Retorno | C43: =FV(Taxa,Periodo*A18,Aporte*-1) -> 13269470 | D43: 2 | E43: 5 | F43: 10 | G43: 20 | H43: 30
C44: 0.006 | D44: 1286560.8 | E44: 3598236.8 | F44: 8750150.5 | G44: 26688117 | H44: 63461272
C45: 0.0065 | D45: 1294125.5 | E45: 3654753.6 | F45: 9045946.3 | G45: 28729682 | H45: 71560958
C46: 0.007 | D46: 1301746.3 | E46: 3712402 | F46: 9354274.1 | G46: 30958891 | H46: 80856878
C47: 0.0075 | D47: 1309423.5 | E47: 3771206.8 | F47: 9675713.9 | G47: 33394343 | H47: 91537174
C48: 0.008 | D48: 1317157.8 | E48: 3831193.3 | F48: 10010873 | G48: 36056561 | H48: 1.0382066e+08
C49: 0.0085 | D49: 1324949.4 | E49: 3892387.4 | F49: 10360390 | G49: 38968189 | H49: 1.1796194e+08
C50: 0.009 | D50: 1332798.9 | E50: 3954815.7 | F50: 10724933 | G50: 42154222 | H50: 1.3425738e+08
C51: 0.0095 | D51: 1340706.7 | E51: 4018505.1 | F51: 11105203 | G51: 45642258 | H51: 1.530521e+08
C52: 0.01 | D52: 1348673.2 | E52: 4083483.5 | F52: 11501934 | G52: 49462768 | H52: 1.7474821e+08
C53: 0.0105 | D53: 1356699.1 | E53: 4149779.2 | F53: 11915899 | G53: 53649411 | H53: 1.9981431e+08
...

Sheet FII's
C1: Agressivo | D1: Moderado | E1: Conservador
B2: PAPEL | C2: 0.5 | D2: 0.32 | E2: 0.3
B3: TIJOLO | C3: 0.1 | D3: 0.35 | E3: 0.5
B4: HÍBRIDOS | C4: 0.05 | D4: 0.08 | E4: 0.1
B5: FOFs | C5: 0.05 | D5: 0.05 | E5: 0.1
B6: DESENVOLVIMENTO | C6: 0.2 | D6: 0.1 | E6: 0
B7: HOTELARIAS | C7: 0.1 | D7: 0.1 | E7: 0
